<?xml version="1.0" encoding="UTF-8"?>
<testsuites>
	<testsuite name="tests.PostTestCase-20201016185712" tests="10" file="tests.py" time="0.014" timestamp="2020-10-16T18:57:12" failures="1" errors="0" skipped="0">
		<testcase classname="tests.PostTestCase" name="test_task10_make_migrations" time="0.005" timestamp="2020-10-16T18:57:12" file="module3/tests.py" line="235">
			<system-out><![CDATA[]]></system-out>
			<system-err><![CDATA[]]></system-err>
		</testcase>
		<testcase classname="tests.PostTestCase" name="test_task1_post_model_exists" time="0.001" timestamp="2020-10-16T18:57:12" file="module3/tests.py" line="111">
			<system-out><![CDATA[]]></system-out>
			<system-err><![CDATA[]]></system-err>
		</testcase>
		<testcase classname="tests.PostTestCase" name="test_task2_author_exists" time="0.001" timestamp="2020-10-16T18:57:12" file="module3/tests.py" line="120">
			<system-out><![CDATA[]]></system-out>
			<system-err><![CDATA[]]></system-err>
		</testcase>
		<testcase classname="tests.PostTestCase" name="test_task3_body_exists" time="0.000" timestamp="2020-10-16T18:57:12" file="module3/tests.py" line="133">
			<system-out><![CDATA[]]></system-out>
			<system-err><![CDATA[]]></system-err>
		</testcase>
		<testcase classname="tests.PostTestCase" name="test_task4_postdate_exists" time="0.001" timestamp="2020-10-16T18:57:12" file="module3/tests.py" line="139">
			<system-out><![CDATA[]]></system-out>
			<system-err><![CDATA[]]></system-err>
		</testcase>
		<testcase classname="tests.PostTestCase" name="test_task5_str_exists" time="0.000" timestamp="2020-10-16T18:57:12" file="module3/tests.py" line="145">
			<system-out><![CDATA[]]></system-out>
			<system-err><![CDATA[]]></system-err>
		</testcase>
		<testcase classname="tests.PostTestCase" name="test_task6_get_abs_url_exists" time="0.000" timestamp="2020-10-16T18:57:12" file="module3/tests.py" line="148">
			<system-out><![CDATA[]]></system-out>
			<system-err><![CDATA[]]></system-err>
		</testcase>
		<testcase classname="tests.PostTestCase" name="test_task7_register_model_in_admin" time="0.001" timestamp="2020-10-16T18:57:12" file="module3/tests.py" line="151">
			<system-out><![CDATA[]]></system-out>
			<system-err><![CDATA[]]></system-err>
		</testcase>
		<testcase classname="tests.PostTestCase" name="test_task8_update_views_with_BlogPost" time="0.002" timestamp="2020-10-16T18:57:12" file="module3/tests.py" line="173">
			<system-out><![CDATA[]]></system-out>
			<system-err><![CDATA[]]></system-err>
		</testcase>
		<testcase classname="tests.PostTestCase" name="test_task9_update_post_view_with_BlogPost" time="0.002" timestamp="2020-10-16T18:57:12" file="module3/tests.py" line="208">
			<failure type="AssertionError" message="Did you set `post` equal to `get_object_or_404`?"><![CDATA[Traceback (most recent call last):
  File "/Users/jmartin/development/python-django-models-authentication/module3/tests.py", line 232, in test_task9_update_post_view_with_BlogPost
    self.assertTrue(set_posts_found, msg="Did you set `post` equal to `get_object_or_404`?")
  File "/Users/jmartin/development/python-django-models-authentication/support/SimplerTestCase.py", line 12, in assertTrue
    self.fail(msg or (str(expr) + "is not True"))
AssertionError: Did you set `post` equal to `get_object_or_404`?
]]></failure>
			<system-out><![CDATA[]]></system-out>
			<system-err><![CDATA[]]></system-err>
		</testcase>
	</testsuite>
</testsuites>
